<robot name="onshape">
    <link name="base">
        <visual>
            <origin xyz="0.0099227436898500984142 0.13827116291230645562 -0.021555193326414485988"
                rpy="0.087266480467832654999 -1.4990033074911502359e-08 -2.2094851261557873804e-08" />
            <geometry>
                <mesh filename="../meshes/NW-V2.0/trunk.stl" />
            </geometry>
            <material name="trunk_material">
                <color rgba="0.2313725490196078538 0.38039215686274507888 0.7058823529411765163 1.0" />
            </material>
        </visual>
        <collision>
            <origin xyz="0.0099227436898500984142 0.13827116291230645562 -0.021555193326414485988"
                rpy="0.087266480467832654999 -1.4990033074911502359e-08 -2.2094851261557873804e-08" />
            <geometry>
                <mesh filename="../meshes/NW-V2.0/trunk.stl" />
            </geometry>
        </collision>
        <inertial>
            <origin xyz="0.0099227428469158013985 0.13391337488491744656 0.028254541500307355645"
                rpy="0 0 0" />
            <mass value="1.0520000000000000462" />
            <inertia ixx="0.0066139164607848304964" ixy="-2.2127823919599840592e-11"
                ixz="-6.4087305219667734827e-11" iyy="0.0053174843071791873944"
                iyz="-0.00043473231152154918205" izz="0.010248462186210406319" />
        </inertial>
    </link>

    <link name="FRH">
        <visual>
            <origin xyz="0.032215611636638621929 0.028555101990604004475 -1.7347234759768070944e-18"
                rpy="1.570796326794896558 1.1108205397628203633e-25 2.389243996016179635e-24" />
            <geometry>
                <mesh filename="../meshes/NW-V2.0/h.stl" />
            </geometry>
            <material name="h_material">
                <color
                    rgba="0.86666666666666669627 0.32156862745098041545 0.15686274509803921351 1.0" />
            </material>
        </visual>
        <collision>
            <origin xyz="0.032215611636638621929 0.028555101990604004475 -1.7347234759768070944e-18"
                rpy="1.570796326794896558 1.1108205397628203633e-25 2.389243996016179635e-24" />
            <geometry>
                <mesh filename="../meshes/NW-V2.0/h.stl" />
            </geometry>
        </collision>
        <inertial>
            <origin xyz="0.021525592503996202054 0 -0.012500000000000004163" rpy="0 0 0" />
            <mass value="0.00899999999999999932" />
            <inertia ixx="1.1139804559497147109e-06" ixy="-4.7104694595813748498e-30"
                ixz="2.1217815524415599108e-30" iyy="3.861958513835964132e-06"
                iyz="4.2501859106604299266e-23" izz="4.0384389697856785015e-06" />
        </inertial>
    </link>

    <link name="FRLU">
        <visual>
            <origin xyz="0 -4.336808689942017736e-19 -0.044999999999999998335"
                rpy="-1.570796326794896558 -1.570796326794896558 0" />
            <geometry>
                <mesh filename="../meshes/NW-V2.0/lu.stl" />
            </geometry>
            <material name="lu_material">
                <color
                    rgba="0.90980392156862743835 0.57254901960784310155 0.16470588235294117418 1.0" />
            </material>
        </visual>
        <collision>
            <origin xyz="0 -4.336808689942017736e-19 -0.044999999999999998335"
                rpy="-1.570796326794896558 -1.570796326794896558 0" />
            <geometry>
                <mesh filename="../meshes/NW-V2.0/lu.stl" />
            </geometry>
        </collision>
        <inertial>
            <origin
                xyz="6.2620707155193050731e-18 -0.049999999999999995837 -0.022499999999999992228"
                rpy="0 0 0" />
            <mass value="0.37600000000000000089" />
            <inertia ixx="0.00054596018323756559387" ixy="-6.2909339871692696768e-21"
                ixz="-2.7466218204555690158e-28" iyy="9.0305640199817038306e-05"
                iyz="-1.1186833988322070734e-27" izz="0.00050936582343738242076" />
        </inertial>
    </link>

    <link name="FRLL">
        <visual>
            <origin
                xyz="-3.4694469519536141888e-18 1.3877787807814456755e-17 -0.024999999999999994449"
                rpy="-1.570796326794896558 -1.570796326794896558 0" />
            <geometry>
                <mesh filename="../meshes/NW-V2.0/ll.stl" />
            </geometry>
            <material name="ll_material">
                <color rgba="1 0.7568627450980391913 0.054901960784313724728 1.0" />
            </material>
        </visual>
        <collision>
            <origin
                xyz="-3.4694469519536141888e-18 1.3877787807814456755e-17 -0.024999999999999994449"
                rpy="-1.570796326794896558 -1.570796326794896558 0" />
            <geometry>
                <mesh filename="../meshes/NW-V2.0/ll.stl" />
            </geometry>
        </collision>
        <inertial>
            <origin
                xyz="1.9694526951946787719e-18 -0.061136909622975924017 -0.012499999999999993755"
                rpy="0 0 0" />
            <mass value="0.058000000000000002942" />
            <inertia ixx="9.3657217382847496073e-05" ixy="1.8944387790966397996e-21"
                ixz="1.9264078887896147153e-28" iyy="9.3296789238021415761e-06"
                iyz="8.0611222752185609261e-29" izz="9.6945229639983001441e-05" />
        </inertial>
    </link>

    <joint name="FRK" type="revolute">
        <origin xyz="1.7347234759768070944e-17 -0.099999999999999991673 -0.045499999999999998779"
            rpy="-7.1116470838921432146e-22 -2.2925350776676440181e-23 3.141592653589753148" />
        <parent link="FRLU" />
        <child link="FRLL" />
        <axis xyz="0 0 1" />
        <limit effort="6.864655" velocity="8.055365759832842" lower="0" upper="3.141592653589793116" />
        <dynamics friction="0.0" />
    </joint>

    <joint name="FRHL" type="revolute">
        <origin xyz="0.055499999999999979905 0 -0.012499999999999997224"
            rpy="-1.570796326794896558 -1.7868117234929788401e-08 1.5707963267948958919" />
        <parent link="FRH" />
        <child link="FRLU" />
        <axis xyz="0 0 1" />
        <limit effort="6.864655" velocity="8.055365759832842" lower="-3.141592653589793116" upper="0" />
        <dynamics friction="0.0" />
    </joint>

    <joint name="FRHU" type="revolute">
        <origin xyz="-0.0650772597514745893 0.0088909421269594522685 0.017316492427308392832"
            rpy="1.4835298463270636393 1.4990033393763916416e-08 3.1415926314949418341" />
        <parent link="base" />
        <child link="FRH" />
        <axis xyz="0 0 1" />
        <limit effort="6.864655" velocity="8.055365759832842" lower="-1.570796326794896558" upper="1.570796326794896558" />
        <dynamics friction="0.0" />
    </joint>

    <link name="FLH">
        <visual>
            <origin xyz="0.032215611636638621929 0.028555101990604007944 -1.7347234759768070944e-18"
                rpy="1.570796326794896558 9.1075724079965769096e-25 1.505906012323039885e-24" />
            <geometry>
                <mesh filename="../meshes/NW-V2.0/h.stl" />
            </geometry>
            <material name="h_material">
                <color
                    rgba="0.86666666666666669627 0.32156862745098041545 0.15686274509803921351 1.0" />
            </material>
        </visual>
        <collision>
            <origin xyz="0.032215611636638621929 0.028555101990604007944 -1.7347234759768070944e-18"
                rpy="1.570796326794896558 9.1075724079965769096e-25 1.505906012323039885e-24" />
            <geometry>
                <mesh filename="../meshes/NW-V2.0/h.stl" />
            </geometry>
        </collision>
        <inertial>
            <origin xyz="0.021525592503996202054 3.4694469519536141888e-18 -0.012500000000000004163"
                rpy="0 0 0" />
            <mass value="0.00899999999999999932" />
            <inertia ixx="1.1139804559497151344e-06" ixy="-1.9689084518447128962e-31"
                ixz="3.3800616490418427527e-30" iyy="3.861958513835964132e-06"
                iyz="-2.7196292853585671399e-23" izz="4.0384389697856785015e-06" />
        </inertial>
    </link>

    <link name="FLLU">
        <visual>
            <origin xyz="0 1.3010426069826053208e-18 0"
                rpy="1.570796326794896558 1.570796326794896558 0" />
            <geometry>
                <mesh filename="../meshes/NW-V2.0/lu.stl" />
            </geometry>
            <material name="lu_material">
                <color
                    rgba="0.90980392156862743835 0.57254901960784310155 0.16470588235294117418 1.0" />
            </material>
        </visual>
        <collision>
            <origin xyz="0 1.3010426069826053208e-18 0"
                rpy="1.570796326794896558 1.570796326794896558 0" />
            <geometry>
                <mesh filename="../meshes/NW-V2.0/lu.stl" />
            </geometry>
        </collision>
        <inertial>
            <origin xyz="5.5616208431659320034e-18 0.050000000000000009714 -0.022500000000000006106"
                rpy="0 0 0" />
            <mass value="0.37600000000000000089" />
            <inertia ixx="0.00054596018323756537703" ixy="-2.2992841737624431057e-21"
                ixz="2.7015283880290629614e-28" iyy="9.0305640199817092516e-05"
                iyz="-9.070826082759685624e-29" izz="0.00050936582343738242076" />
        </inertial>
    </link>

    <link name="FLLL">
        <visual>
            <origin xyz="3.4694469519536141888e-18 0 0"
                rpy="1.570796326794896558 1.570796326794896558 0" />
            <geometry>
                <mesh filename="../meshes/NW-V2.0/ll.stl" />
            </geometry>
            <material name="ll_material">
                <color rgba="1 0.7568627450980391913 0.054901960784313724728 1.0" />
            </material>
        </visual>
        <collision>
            <origin xyz="3.4694469519536141888e-18 0 0"
                rpy="1.570796326794896558 1.570796326794896558 0" />
            <geometry>
                <mesh filename="../meshes/NW-V2.0/ll.stl" />
            </geometry>
        </collision>
        <inertial>
            <origin xyz="9.2137019453039912532e-18 0.061136909622975937895 -0.012500000000000002429"
                rpy="0 0 0" />
            <mass value="0.058000000000000002942" />
            <inertia ixx="9.3657217382847523179e-05" ixy="1.3290574521296748718e-21"
                ixz="6.6457046954983543975e-31" iyy="9.3296789238021415761e-06"
                iyz="1.7231724855193558632e-28" izz="9.6945229639983001441e-05" />
        </inertial>
    </link>

    <joint name="FLK" type="revolute">
        <origin xyz="1.0408340855860842566e-17 0.10000000000000001943 -0.045499999999999984901"
            rpy="-7.8652590286309986181e-18 -4.7062504561224808517e-16 3.1415926520183123927" />
        <parent link="FLLU" />
        <child link="FLLL" />
        <axis xyz="0 0 1" />
        <limit effort="6.864655" velocity="8.055365759832842" lower="-3.141592653589793116" upper="0" />
        <dynamics friction="0.0" />
    </joint>

    <joint name="FLHL" type="revolute">
        <origin xyz="0.055499999999999966027 3.4694469519536141888e-18 -0.012500000000000000694"
            rpy="1.570796326794896558 -4.159598675987668933e-09 -1.5707963267948958919" />
        <parent link="FLH" />
        <child link="FLLU" />
        <axis xyz="0 0 1" />
        <limit effort="6.864655" velocity="8.055365759832842" lower="0" upper="3.141592653589793116" />
        <dynamics friction="0.0" />
    </joint>

    <joint name="FLHU" type="revolute">
        <origin xyz="0.084922740248525377393 0.0088909388127318342288 0.017316494675813358384"
            rpy="-1.4835298463270638614 6.7904519714569485168e-09 -2.0189305413825018056e-08" />
        <parent link="base" />
        <child link="FLH" />
        <axis xyz="0 0 1" />
        <limit effort="6.864655" velocity="8.055365759832842" lower="-1.570796326794896558" upper="1.570796326794896558" />
        <dynamics friction="0.0" />
    </joint>

    <link name="BLH">
        <visual>
            <origin xyz="0.032215611636638649684 -0.028555101990604011414 -0.025000000000000022204"
                rpy="-1.570796326794896558 -8.10198965264292864e-25 9.4990879062215657594e-26" />
            <geometry>
                <mesh filename="../meshes/NW-V2.0/h.stl" />
            </geometry>
            <material name="h_material">
                <color
                    rgba="0.86666666666666669627 0.32156862745098041545 0.15686274509803921351 1.0" />
            </material>
        </visual>
        <collision>
            <origin xyz="0.032215611636638649684 -0.028555101990604011414 -0.025000000000000022204"
                rpy="-1.570796326794896558 -8.10198965264292864e-25 9.4990879062215657594e-26" />
            <geometry>
                <mesh filename="../meshes/NW-V2.0/h.stl" />
            </geometry>
        </collision>
        <inertial>
            <origin xyz="0.02152559250399622981 -6.9388939039072283776e-18 -0.012500000000000016306"
                rpy="0 0 0" />
            <mass value="0.00899999999999999932" />
            <inertia ixx="1.1139804559497151344e-06" ixy="5.4442413068550466113e-31"
                ixz="1.6844066981830147865e-30" iyy="3.861958513835964132e-06"
                iyz="8.6849436149024947476e-23" izz="4.0384389697856801956e-06" />
        </inertial>
    </link>

    <link name="BLLU">
        <visual>
            <origin xyz="0 5.5511151231257827021e-17 0"
                rpy="1.570796326794896558 1.570796326794896558 0" />
            <geometry>
                <mesh filename="../meshes/NW-V2.0/lu.stl" />
            </geometry>
            <material name="lu_material">
                <color
                    rgba="0.90980392156862743835 0.57254901960784310155 0.16470588235294117418 1.0" />
            </material>
        </visual>
        <collision>
            <origin xyz="0 5.5511151231257827021e-17 0"
                rpy="1.570796326794896558 1.570796326794896558 0" />
            <geometry>
                <mesh filename="../meshes/NW-V2.0/lu.stl" />
            </geometry>
        </collision>
        <inertial>
            <origin xyz="5.9211816862429063451e-18 0.050000000000000051348 -0.022500000000000006106"
                rpy="0 0 0" />
            <mass value="0.37600000000000000089" />
            <inertia ixx="0.00054596018323756537703" ixy="1.1357734578361653713e-21"
                ixz="1.6575077737249074558e-29" iyy="9.0305640199817038306e-05"
                iyz="-7.7086529605856559569e-28" izz="0.00050936582343738242076" />
        </inertial>
    </link>

    <link name="BLLL">
        <visual>
            <origin xyz="0 0 0" rpy="1.570796326794896558 1.570796326794896558 0" />
            <geometry>
                <mesh filename="../meshes/NW-V2.0/ll.stl" />
            </geometry>
            <material name="ll_material">
                <color rgba="1 0.7568627450980391913 0.054901960784313724728 1.0" />
            </material>
        </visual>
        <collision>
            <origin xyz="0 0 0" rpy="1.570796326794896558 1.570796326794896558 0" />
            <geometry>
                <mesh filename="../meshes/NW-V2.0/ll.stl" />
            </geometry>
        </collision>
        <inertial>
            <origin xyz="3.7390117916974263243e-18 0.061136909622975937895 -0.012500000000000002429"
                rpy="0 0 0" />
            <mass value="0.058000000000000002942" />
            <inertia ixx="9.3657217382847577389e-05" ixy="-4.5788073598597142278e-22"
                ixz="-8.9882329698141926452e-30" iyy="9.3296789238021415761e-06"
                iyz="3.1104732328345604965e-28" izz="9.6945229639983001441e-05" />
        </inertial>
    </link>

    <joint name="BLK" type="revolute">
        <origin xyz="1.3877787807814456755e-17 0.10000000000000003331 -0.045500000000000040412"
            rpy="1.4434690318418828902e-23 -2.1427618407478369809e-16 3.1415926503251903057" />
        <parent link="BLLU" />
        <child link="BLLL" />
        <axis xyz="0 0 1" />
        <limit effort="6.864655" velocity="8.055365759832842" lower="-3.141592653589793116" upper="0" />
        <dynamics friction="0.0" />
    </joint>

    <joint name="BLHL" type="revolute">
        <origin xyz="0.055500000000000021538 -6.9388939039072283776e-18 -0.012500000000000011102"
            rpy="-1.570796326794896558 4.159598612862823089e-09 1.57079632679489678" />
        <parent link="BLH" />
        <child link="BLLU" />
        <axis xyz="0 0 1" />
        <limit effort="6.864655" velocity="8.055365759832842" lower="0" upper="3.141592653589793116" />
        <dynamics friction="0.0" />
    </joint>

    <joint name="BLHU" type="revolute">
        <origin xyz="0.084922745445306119239 0.2589358076428754929 0.039192590573306332336"
            rpy="1.6580628072627294767 1.8044978216328643843e-09 -2.0625520126565480844e-08" />
        <parent link="base" />
        <child link="BLH" />
        <axis xyz="0 0 1" />
        <limit effort="6.864655" velocity="8.055365759832842" lower="-1.570796326794896558" upper="1.570796326794896558" />
        <dynamics friction="0.0" />
    </joint>

    <link name="BRH">
        <visual>
            <origin xyz="0.032215611636638635806 -0.028555101990604011414 -0.025000000000000022204"
                rpy="-1.570796326794896558 -1.4998403820108036855e-24 -4.3122347891137220117e-26" />
            <geometry>
                <mesh filename="../meshes/NW-V2.0/h.stl" />
            </geometry>
            <material name="h_material">
                <color
                    rgba="0.86666666666666669627 0.32156862745098041545 0.15686274509803921351 1.0" />
            </material>
        </visual>
        <collision>
            <origin xyz="0.032215611636638635806 -0.028555101990604011414 -0.025000000000000022204"
                rpy="-1.570796326794896558 -1.4998403820108036855e-24 -4.3122347891137220117e-26" />
            <geometry>
                <mesh filename="../meshes/NW-V2.0/h.stl" />
            </geometry>
        </collision>
        <inertial>
            <origin
                xyz="0.021525592503996215932 -6.9388939039072283776e-18 -0.012500000000000016306"
                rpy="0 0 0" />
            <mass value="0.00899999999999999932" />
            <inertia ixx="1.1139804559497151344e-06" ixy="9.3627191242228522523e-32"
                ixz="-4.7049295494197789846e-30" iyy="3.861958513835964132e-06"
                iyz="-1.4219191714590580432e-22" izz="4.0384389697856801956e-06" />
        </inertial>
    </link>

    <link name="BRLU">
        <visual>
            <origin xyz="-6.9388939039072283776e-18 0 -0.045000000000000012212"
                rpy="-1.570796326794896558 -1.570796326794896558 0" />
            <geometry>
                <mesh filename="../meshes/NW-V2.0/lu.stl" />
            </geometry>
            <material name="lu_material">
                <color
                    rgba="0.90980392156862743835 0.57254901960784310155 0.16470588235294117418 1.0" />
            </material>
        </visual>
        <collision>
            <origin xyz="-6.9388939039072283776e-18 0 -0.045000000000000012212"
                rpy="-1.570796326794896558 -1.570796326794896558 0" />
            <geometry>
                <mesh filename="../meshes/NW-V2.0/lu.stl" />
            </geometry>
        </collision>
        <inertial>
            <origin
                xyz="-1.3050027554235737557e-18 -0.049999999999999995837 -0.022500000000000006106"
                rpy="0 0 0" />
            <mass value="0.37600000000000000089" />
            <inertia ixx="0.00054596018323756516019" ixy="6.9271241937707520723e-21"
                ixz="3.9087517827652982159e-29" iyy="9.0305640199817065411e-05"
                iyz="-1.0600944170879576797e-27" izz="0.00050936582343738242076" />
        </inertial>
    </link>

    <link name="BRLL">
        <visual>
            <origin xyz="0 0 -0.024999999999999966693"
                rpy="-1.570796326794896558 -1.570796326794896558 0" />
            <geometry>
                <mesh filename="../meshes/NW-V2.0/ll.stl" />
            </geometry>
            <material name="ll_material">
                <color rgba="1 0.7568627450980391913 0.054901960784313724728 1.0" />
            </material>
        </visual>
        <collision>
            <origin xyz="0 0 -0.024999999999999966693"
                rpy="-1.570796326794896558 -1.570796326794896558 0" />
            <geometry>
                <mesh filename="../meshes/NW-V2.0/ll.stl" />
            </geometry>
        </collision>
        <inertial>
            <origin
                xyz="4.7280846165466977846e-18 -0.061136909622975930956 -0.012499999999999964265"
                rpy="0 0 0" />
            <mass value="0.058000000000000002942" />
            <inertia ixx="9.3657217382847496073e-05" ixy="1.648354660558725678e-21"
                ixz="-8.8628767452269501285e-30" iyy="9.3296789238021381879e-06"
                iyz="5.3997135265007114694e-28" izz="9.6945229639983001441e-05" />
        </inertial>
    </link>

    <joint name="BRK" type="revolute">
        <origin xyz="6.9388939039072283776e-18 -0.10000000000000003331 -0.045500000000000012657"
            rpy="2.4133500580982883301e-16 -8.1245406211814635824e-17 -3.1415926503251419" />
        <parent link="BRLU" />
        <child link="BRLL" />
        <axis xyz="0 0 1" />
        <limit effort="6.864655" velocity="8.055365759832842" lower="0" upper="3.141592653589793116" />
        <dynamics friction="0.0" />
    </joint>

    <joint name="BRHL" type="revolute">
        <origin xyz="0.055499999999999993783 -1.3877787807814456755e-17 -0.012500000000000011102"
            rpy="1.570796326794896558 4.1595986025831493502e-09 -1.5707963267948985564" />
        <parent link="BRH" />
        <child link="BRLU" />
        <axis xyz="0 0 1" />
        <limit effort="6.864655" velocity="8.055365759832842" lower="-3.141592653589793116" upper="0" />
        <dynamics friction="0.0" />
    </joint>

    <joint name="BRHU" type="revolute">
        <origin xyz="-0.065077254554693611532 0.25893581095710316298 0.039192588324801366784"
            rpy="-1.6580628072627294767 -1.8044955021529479955e-09 3.1415926329642727133" />
        <parent link="base" />
        <child link="BRH" />
        <axis xyz="0 0 1" />
        <limit effort="6.864655" velocity="8.055365759832842" lower="-1.570796326794896558" upper="1.570796326794896558" />
        <dynamics friction="0.0" />
    </joint>


</robot>