<?xml version="1.0" encoding="utf-8"?>
<robot name="wheely">
    <link name="base">
        <visual>
            <origin rpy="0 0 0" xyz="0 0 0" />
            <geometry>
                <box size="0.001 0.001 0.001" />
            </geometry>
        </visual>
    </link>
    <joint name="floating_base" type="fixed">
        <origin rpy="0 0 0" xyz="0 0 0" />
        <parent link="base" />
        <child link="trunk" />
    </joint>
    <link name="trunk">
        <visual>
            <origin xyz="0.016085846076173661995 0.168115314486978501 -0.079626516931856003434"
                rpy="0.087266479572840227608 1.1592872166690008089e-09 -1.3250729495637539251e-08" />
            <geometry>
                <mesh filename="../meshes/V2.7/main_body_sim.stl" />
            </geometry>
            <material name="main_body_sim_material">
                <color rgba="0.2313725490196078538 0.38039215686274507888 0.7058823529411765163 1.0" />
            </material>
        </visual>
        <collision>
            <origin xyz="0.016085846076173661995 0.168115314486978501 -0.079626516931856003434"
                rpy="0.087266479572840227608 1.1592872166690008089e-09 -1.3250729495637539251e-08" />
            <geometry>
                <mesh filename="../meshes/V2.7/main_body_sim.stl" />
            </geometry>
        </collision>
        <inertial>
            <origin xyz="0.016085846076173533625 0.16375752650416883216 -0.029816782101233972602"
                rpy="0 0 0" />
            <mass value="1.0520000000000002682" />
            <inertia ixx="0.0066139164607848287616" ixy="-1.7682651499246315317e-11"
                ixz="-1.5470365969232099219e-12" iyy="0.0053174843064010216681"
                iyz="-0.00043473230710836267745" izz="0.010248462186988568576" />
        </inertial>
    </link>

    <link name="FRH">
        <visual>
            <origin xyz="0.032215611636638628867 0.028555101990604014883 0"
                rpy="1.570796326794896558 -4.2438333867592718619e-25 4.6771345179228599959e-26" />
            <geometry>
                <mesh filename="../meshes/V2.7/hip_joint_sim.stl" />
            </geometry>
            <material name="hip_joint_sim_material">
                <color
                    rgba="0.86666666666666669627 0.32156862745098041545 0.15686274509803921351 1.0" />
            </material>
        </visual>
        <collision>
            <origin xyz="0.032215611636638628867 0.028555101990604014883 0"
                rpy="1.570796326794896558 -4.2438333867592718619e-25 4.6771345179228599959e-26" />
            <geometry>
                <mesh filename="../meshes/V2.7/hip_joint_sim.stl" />
            </geometry>
        </collision>
        <inertial>
            <origin xyz="0.021525592503996208993 1.0408340855860842566e-17 -0.012500000000000000694"
                rpy="0 0 0" />
            <mass value="0.0090000000000000010547" />
            <inertia ixx="1.1139804559497151344e-06" ixy="-5.7653600179275655136e-32"
                ixz="4.5802622107353119717e-30" iyy="3.861958513835964979e-06"
                iyz="1.6881355714084500069e-23" izz="4.0384389697856793485e-06" />
        </inertial>
    </link>

    <link name="FRUL">
        <visual>
            <origin xyz="0 -3.4694469519536141888e-18 -0.044999999999999984457"
                rpy="-1.570796326794896558 -1.570796326794896558 0" />
            <geometry>
                <mesh filename="../meshes/V2.7/leg_upper_sim.stl" />
            </geometry>
            <material name="leg_upper_sim_material">
                <color
                    rgba="0.90980392156862743835 0.57254901960784310155 0.16470588235294117418 1.0" />
            </material>
        </visual>
        <collision>
            <origin xyz="0 -3.4694469519536141888e-18 -0.044999999999999984457"
                rpy="-1.570796326794896558 -1.570796326794896558 0" />
            <geometry>
                <mesh filename="../meshes/V2.7/leg_upper_sim.stl" />
            </geometry>
        </collision>
        <inertial>
            <origin
                xyz="6.2383065914996698518e-18 -0.049999999999999995837 -0.022499999999999978351"
                rpy="0 0 0" />
            <mass value="0.37600000000000000089" />
            <inertia ixx="0.00054596018323756537703" ixy="-3.6081502289419232503e-21"
                ixz="-1.5570501078285423572e-28" iyy="9.0305640199817024754e-05"
                iyz="-1.0816533961556011352e-27" izz="0.00050936582343738242076" />
        </inertial>
    </link>

    <link name="FRLL">
        <visual>
            <origin xyz="-6.9388939039072283776e-18 0 -0.025000000000000022204"
                rpy="-1.570796326794896558 -1.570796326794896558 0" />
            <geometry>
                <mesh filename="../meshes/V2.7/leg_lower_sim.stl" />
            </geometry>
            <material name="leg_lower_sim_material">
                <color rgba="1 0.7568627450980391913 0.054901960784313724728 1.0" />
            </material>
        </visual>
        <collision>
            <origin xyz="-6.9388939039072283776e-18 0 -0.025000000000000022204"
                rpy="-1.570796326794896558 -1.570796326794896558 0" />
            <geometry>
                <mesh filename="../meshes/V2.7/leg_lower_sim.stl" />
            </geometry>
        </collision>
        <inertial>
            <origin
                xyz="-1.6565681861865563553e-18 -0.061136909622975930956 -0.012500000000000019776"
                rpy="0 0 0" />
            <mass value="0.058000000000000002942" />
            <inertia ixx="9.3657217382847455416e-05" ixy="8.7623385824824253441e-22"
                ixz="-8.0076840611424203394e-30" iyy="9.3296789238021381879e-06"
                iyz="2.7174534049753015943e-28" izz="9.6945229639982987888e-05" />
        </inertial>
    </link>

    <link name="FRW">
        <visual>
            <origin xyz="-0.087087206542491898964 -0.02704686298966407082 -0.014999999999999985567"
                rpy="-1.570796326794896558 -1.570796326794896558 0" />
            <geometry>
                <mesh filename="../meshes/V2.7/wheel_sim.stl" />
            </geometry>
            <material name="wheel_sim_material">
                <color
                    rgba="0.64705882352941179736 0.64705882352941179736 0.64705882352941179736 1.0" />
            </material>
        </visual>
        <collision>
            <origin xyz="-0.087087206542491898964 -0.02704686298966407082 -0.014999999999999985567"
                rpy="-1.570796326794896558 -1.570796326794896558 0" />
            <geometry>
                <mesh filename="../meshes/V2.7/wheel_sim.stl" />
            </geometry>
        </collision>
        <inertial>
            <origin
                xyz="1.3527462244954900352e-17 3.4694469519536141888e-18 -0.007499999999999986712"
                rpy="0 0 0" />
            <mass value="0.036999999999999998168" />
            <inertia ixx="2.3186407739588025368e-05" ixy="-4.9990566576337651389e-22"
                ixz="-7.9693294831989268377e-30" iyy="2.3186407739588018592e-05"
                iyz="-4.276202136615104681e-30" izz="4.5033754578493196004e-05" />
        </inertial>
    </link>

    <joint name="FRW joint" type="revolute">
        <origin xyz="-2.0816681711721685133e-17 -0.099999999999999880651 -0.025500000000000022649"
            rpy="-7.9092802216408258593e-24 6.8814771349931104597e-24 1.570796326794896558" />
        <parent link="FRLL" />
        <child link="FRW" />
        <axis xyz="0 0 1" />
        <limit effort="3.43" velocity="1.5707" />
        <joint_properties friction="0.0" />
    </joint>

    <joint name="FRK joint" type="revolute">
        <origin xyz="1.3877787807814456755e-17 -0.10000000000000000555 -0.045499999999999957145"
            rpy="5.0864344218527357745e-16 -8.2215564428531773414e-17 3.141592653589753148" />
        <parent link="FRUL" />
        <child link="FRLL" />
        <axis xyz="0 0 1" />
        <limit effort="6.864655" velocity="8.055365759832842" lower="0" upper="3.141592653589793116" />
        <joint_properties friction="0.0" />
    </joint>

    <joint name="FRHL joint" type="revolute">
        <origin xyz="0.055499999999999986844 6.9388939039072283776e-18 -0.012500000000000004163"
            rpy="-1.57079632679489678 -1.6973124467726718736e-08 1.5707963267948958919" />
        <parent link="FRH" />
        <child link="FRUL" />
        <axis xyz="0 0 1" />
        <limit effort="6.864655" velocity="8.055365759832842" lower="-3.141592653589793116" upper="0" />
        <joint_properties friction="0.0" />
    </joint>

    <joint name="FRHU joint" type="revolute">
        <origin xyz="-0.058914155593145264844 0.038735093073112264461 -0.040754829851139789954"
            rpy="1.4835298472220561639 -1.1592871302188590348e-09 3.1415926403390632693" />
        <parent link="trunk" />
        <child link="FRH" />
        <axis xyz="0 0 1" />
        <limit effort="6.864655" velocity="8.055365759832842" lower="-0.75" upper="0.75" />
        <joint_properties friction="0.0" />
    </joint>

    <link name="FLH">
        <visual>
            <origin xyz="0.032215611636638635806 0.028555101990604007944 0"
                rpy="1.570796326794896558 7.0286894079455799334e-25 -5.5953751071726945294e-26" />
            <geometry>
                <mesh filename="../meshes/V2.7/hip_joint_sim.stl" />
            </geometry>
            <material name="hip_joint_sim_material">
                <color
                    rgba="0.86666666666666669627 0.32156862745098041545 0.15686274509803921351 1.0" />
            </material>
        </visual>
        <collision>
            <origin xyz="0.032215611636638635806 0.028555101990604007944 0"
                rpy="1.570796326794896558 7.0286894079455799334e-25 -5.5953751071726945294e-26" />
            <geometry>
                <mesh filename="../meshes/V2.7/hip_joint_sim.stl" />
            </geometry>
        </collision>
        <inertial>
            <origin xyz="0.021525592503996215932 6.9388939039072283776e-18 -0.012500000000000000694"
                rpy="0 0 0" />
            <mass value="0.0090000000000000010547" />
            <inertia ixx="1.1139804559497151344e-06" ixy="6.9890069904689581073e-31"
                ixz="-4.204026939458761193e-30" iyy="3.8619585138359632849e-06"
                iyz="-3.4197126064241064045e-23" izz="4.0384389697856793485e-06" />
        </inertial>
    </link>

    <link name="FLUL">
        <visual>
            <origin xyz="0 0 -2.7755575615628913511e-17"
                rpy="1.570796326794896558 1.570796326794896558 0" />
            <geometry>
                <mesh filename="../meshes/V2.7/leg_upper_sim.stl" />
            </geometry>
            <material name="leg_upper_sim_material">
                <color
                    rgba="0.90980392156862743835 0.57254901960784310155 0.16470588235294117418 1.0" />
            </material>
        </visual>
        <collision>
            <origin xyz="0 0 -2.7755575615628913511e-17"
                rpy="1.570796326794896558 1.570796326794896558 0" />
            <geometry>
                <mesh filename="../meshes/V2.7/leg_upper_sim.stl" />
            </geometry>
        </collision>
        <inertial>
            <origin xyz="5.1875742030047978415e-18 0.049999999999999995837 -0.022500000000000033862"
                rpy="0 0 0" />
            <mass value="0.37600000000000000089" />
            <inertia ixx="0.00054596018323756516019" ixy="4.5992593113879710026e-22"
                ixz="-1.4525527803094125949e-28" iyy="9.0305640199817024754e-05"
                iyz="1.9258726447419818821e-28" izz="0.00050936582343738242076" />
        </inertial>
    </link>

    <link name="FLLL">
        <visual>
            <origin xyz="6.9388939039072283776e-18 -1.3877787807814456755e-17 0"
                rpy="1.570796326794896558 1.570796326794896558 0" />
            <geometry>
                <mesh filename="../meshes/V2.7/leg_lower_sim.stl" />
            </geometry>
            <material name="leg_lower_sim_material">
                <color rgba="1 0.7568627450980391913 0.054901960784313724728 1.0" />
            </material>
        </visual>
        <collision>
            <origin xyz="6.9388939039072283776e-18 -1.3877787807814456755e-17 0"
                rpy="1.570796326794896558 1.570796326794896558 0" />
            <geometry>
                <mesh filename="../meshes/V2.7/leg_lower_sim.stl" />
            </geometry>
        </collision>
        <inertial>
            <origin xyz="1.222748492973559549e-17 0.061136909622975910139 -0.012500000000000002429"
                rpy="0 0 0" />
            <mass value="0.058000000000000002942" />
            <inertia ixx="9.3657217382847482521e-05" ixy="2.6094494728404816957e-22"
                ixz="2.5647267860967063194e-29" iyy="9.3296789238021381879e-06"
                iyz="-6.9440235685524328369e-29" izz="9.6945229639982987888e-05" />
        </inertial>
    </link>

    <link name="FLW">
        <visual>
            <origin xyz="-0.087087206542491912842 0.027046862989664084698 0"
                rpy="1.570796326794896558 1.570796326794896558 0" />
            <geometry>
                <mesh filename="../meshes/V2.7/wheel_sim.stl" />
            </geometry>
            <material name="wheel_sim_material">
                <color
                    rgba="0.64705882352941179736 0.64705882352941179736 0.64705882352941179736 1.0" />
            </material>
        </visual>
        <collision>
            <origin xyz="-0.087087206542491912842 0.027046862989664084698 0"
                rpy="1.570796326794896558 1.570796326794896558 0" />
            <geometry>
                <mesh filename="../meshes/V2.7/wheel_sim.stl" />
            </geometry>
        </collision>
        <inertial>
            <origin
                xyz="-1.7881189760053742421e-19 1.0408340855860842566e-17 -0.0074999999999999997224"
                rpy="0 0 0" />
            <mass value="0.036999999999999998168" />
            <inertia ixx="2.3186407739588025368e-05" ixy="4.3937121173749151425e-22"
                ixz="-7.0408485960714528607e-30" iyy="2.3186407739588018592e-05"
                iyz="3.4889273503835089843e-31" izz="4.5033754578493196004e-05" />
        </inertial>
    </link>

    <joint name="FLW joint" type="revolute">
        <origin xyz="-6.3143934525555778237e-16 0.099999999999997687961 -0.025499999999999994893"
            rpy="3.5388568884116363061e-16 -1.2337535347084987515e-22 -1.570796326794896336" />
        <parent link="FLLL" />
        <child link="FLW" />
        <axis xyz="0 0 1" />
        <limit effort="3.43" velocity="1.5707" />
        <joint_properties friction="0.0" />
    </joint>

    <joint name="FLK joint" type="revolute">
        <origin xyz="6.9388939039072283776e-18 0.099999999999999991673 -0.045500000000000012657"
            rpy="-7.5536900123638314732e-24 -6.018276161768133612e-25 -3.141592653589793116" />
        <parent link="FLUL" />
        <child link="FLLL" />
        <axis xyz="0 0 1" />
        <limit effort="6.864655" velocity="8.055365759832842" lower="-3.141592653589793116" upper="0" />
        <joint_properties friction="0.0" />
    </joint>

    <joint name="FLHL joint" type="revolute">
        <origin xyz="0.055500000000000021538 0 -0.012499999999999993755"
            rpy="1.570796326794896558 6.8272161205998660935e-17 -1.570796326794896558" />
        <parent link="FLH" />
        <child link="FLUL" />
        <axis xyz="0 0 1" />
        <limit effort="6.864655" velocity="8.055365759832842" lower="0" upper="3.141592653589793116" />
        <joint_properties friction="0.0" />
    </joint>

    <joint name="FLHU joint" type="revolute">
        <origin xyz="0.091085844406854715727 0.038735091085502881825 -0.040754830025032842689"
            rpy="-1.4835298472220563859 1.1592872166690003953e-09 -1.3250729495637545868e-08" />
        <parent link="trunk" />
        <child link="FLH" />
        <axis xyz="0 0 1" />
        <limit effort="6.864655" velocity="8.055365759832842" lower="-0.75" upper="0.75" />
        <joint_properties friction="0.0" />
    </joint>

    <link name="BLH">
        <visual>
            <origin xyz="0.032215611636638635806 -0.028555101990604001005 -0.024999999999999966693"
                rpy="-1.570796326794896558 1.0698161546298271925e-25 -7.5375053624197476213e-26" />
            <geometry>
                <mesh filename="../meshes/V2.7/hip_joint_sim.stl" />
            </geometry>
            <material name="hip_joint_sim_material">
                <color
                    rgba="0.86666666666666669627 0.32156862745098041545 0.15686274509803921351 1.0" />
            </material>
        </visual>
        <collision>
            <origin xyz="0.032215611636638635806 -0.028555101990604001005 -0.024999999999999966693"
                rpy="-1.570796326794896558 1.0698161546298271925e-25 -7.5375053624197476213e-26" />
            <geometry>
                <mesh filename="../meshes/V2.7/hip_joint_sim.stl" />
            </geometry>
        </collision>
        <inertial>
            <origin xyz="0.021525592503996215932 0 -0.012499999999999965999" rpy="0 0 0" />
            <mass value="0.0090000000000000010547" />
            <inertia ixx="1.1139804559497151344e-06" ixy="7.2818587311957498518e-31"
                ixz="6.215385234648518443e-30" iyy="3.8619585138359632849e-06"
                iyz="-8.9527515258008484814e-23" izz="4.0384389697856793485e-06" />
        </inertial>
    </link>

    <link name="BLUL">
        <visual>
            <origin xyz="-6.9388939039072283776e-18 0 0"
                rpy="1.570796326794896558 1.570796326794896558 0" />
            <geometry>
                <mesh filename="../meshes/V2.7/leg_upper_sim.stl" />
            </geometry>
            <material name="leg_upper_sim_material">
                <color
                    rgba="0.90980392156862743835 0.57254901960784310155 0.16470588235294117418 1.0" />
            </material>
        </visual>
        <collision>
            <origin xyz="-6.9388939039072283776e-18 0 0"
                rpy="1.570796326794896558 1.570796326794896558 0" />
            <geometry>
                <mesh filename="../meshes/V2.7/leg_upper_sim.stl" />
            </geometry>
        </collision>
        <inertial>
            <origin xyz="-1.3627131306886245e-18 0.049999999999999995837 -0.022500000000000006106"
                rpy="0 0 0" />
            <mass value="0.37600000000000000089" />
            <inertia ixx="0.00054596018323756516019" ixy="4.2645847665350335368e-21"
                ixz="3.8306015682044421008e-29" iyy="9.0305640199817024754e-05"
                iyz="-6.0513618616234192516e-28" izz="0.00050936582343738242076" />
        </inertial>
    </link>

    <link name="BLLL">
        <visual>
            <origin xyz="0 5.5511151231257827021e-17 0"
                rpy="1.570796326794896558 1.570796326794896558 0" />
            <geometry>
                <mesh filename="../meshes/V2.7/leg_lower_sim.stl" />
            </geometry>
            <material name="leg_lower_sim_material">
                <color rgba="1 0.7568627450980391913 0.054901960784313724728 1.0" />
            </material>
        </visual>
        <collision>
            <origin xyz="0 5.5511151231257827021e-17 0"
                rpy="1.570796326794896558 1.570796326794896558 0" />
            <geometry>
                <mesh filename="../meshes/V2.7/leg_lower_sim.stl" />
            </geometry>
        </collision>
        <inertial>
            <origin xyz="5.0296824213936827412e-18 0.061136909622975993406 -0.012500000000000002429"
                rpy="0 0 0" />
            <mass value="0.058000000000000002942" />
            <inertia ixx="9.3657217382847563836e-05" ixy="1.552176727869005346e-21"
                ixz="-1.6401783152993076353e-29" iyy="9.3296789238021415761e-06"
                iyz="6.6270565955543233865e-29" izz="9.6945229639982987888e-05" />
        </inertial>
    </link>

    <link name="BLW">
        <visual>
            <origin xyz="-0.087087206542491968353 0.027046862989664081228 0"
                rpy="1.570796326794896558 1.570796326794896558 0" />
            <geometry>
                <mesh filename="../meshes/V2.7/wheel_sim.stl" />
            </geometry>
            <material name="wheel_sim_material">
                <color
                    rgba="0.64705882352941179736 0.64705882352941179736 0.64705882352941179736 1.0" />
            </material>
        </visual>
        <collision>
            <origin xyz="-0.087087206542491968353 0.027046862989664081228 0"
                rpy="1.570796326794896558 1.570796326794896558 0" />
            <geometry>
                <mesh filename="../meshes/V2.7/wheel_sim.stl" />
            </geometry>
        </collision>
        <inertial>
            <origin
                xyz="-6.93602761975395483e-17 3.4694469519536141888e-18 -0.0074999999999999997224"
                rpy="0 0 0" />
            <mass value="0.036999999999999998168" />
            <inertia ixx="2.3186407739588018592e-05" ixy="-2.1352802728494658065e-22"
                ixz="-1.7444581624479791579e-29" iyy="2.3186407739588025368e-05"
                iyz="2.5821388284746647044e-30" izz="4.5033754578493196004e-05" />
        </inertial>
    </link>

    <joint name="BLW joint" type="revolute">
        <origin xyz="3.4694469519536141888e-17 0.10000000000000014433 -0.025499999999999967137"
            rpy="4.5045183749304534022e-24 8.6362713993684203648e-24 1.570796326794896558" />
        <parent link="BLLL" />
        <child link="BLW" />
        <axis xyz="0 0 1" />
        <limit effort="3.43" velocity="1.5707" />
        <joint_properties friction="0.0" />
    </joint>

    <joint name="BLK joint" type="revolute">
        <origin xyz="1.3877787807814456755e-17 0.099999999999999977796 -0.045500000000000012657"
            rpy="1.3021092769811203887e-23 3.6041219465857317813e-22 -3.1415926535897900074" />
        <parent link="BLUL" />
        <child link="BLLL" />
        <axis xyz="0 0 1" />
        <limit effort="6.864655" velocity="8.055365759832842" lower="-3.141592653589793116" upper="0" />
        <joint_properties friction="0.0" />
    </joint>

    <joint name="BLHL joint" type="revolute">
        <origin xyz="0.055500000000000049294 -6.9388939039072283776e-18 -0.012499999999999955591"
            rpy="-1.570796326794896558 7.5920985382837631167e-18 1.570796326794896558" />
        <parent link="BLH" />
        <child link="BLUL" />
        <axis xyz="0 0 1" />
        <limit effort="6.864655" velocity="8.055365759832842" lower="0" upper="3.141592653589793116" />
        <joint_properties friction="0.0" />
    </joint>

    <joint name="BLHU joint" type="revolute">
        <origin xyz="0.091085847745492304339 0.28877995993522542761 -0.018878734351328172597"
            rpy="1.6580628063677369521 1.1592872998405336429e-09 -1.3250729769561944394e-08" />
        <parent link="trunk" />
        <child link="BLH" />
        <axis xyz="0 0 1" />
        <limit effort="6.864655" velocity="8.055365759832842" lower="-0.75" upper="0.75" />
        <joint_properties friction="0.0" />
    </joint>

    <link name="BRH">
        <visual>
            <origin xyz="0.032215611636638635806 -0.028555101990604007944 -0.025000000000000022204"
                rpy="-1.570796326794896558 2.5857472753861947361e-25 3.7124116759250925537e-25" />
            <geometry>
                <mesh filename="../meshes/V2.7/hip_joint_sim.stl" />
            </geometry>
            <material name="hip_joint_sim_material">
                <color
                    rgba="0.86666666666666669627 0.32156862745098041545 0.15686274509803921351 1.0" />
            </material>
        </visual>
        <collision>
            <origin xyz="0.032215611636638635806 -0.028555101990604007944 -0.025000000000000022204"
                rpy="-1.570796326794896558 2.5857472753861947361e-25 3.7124116759250925537e-25" />
            <geometry>
                <mesh filename="../meshes/V2.7/hip_joint_sim.stl" />
            </geometry>
        </collision>
        <inertial>
            <origin
                xyz="0.021525592503996215932 -6.9388939039072283776e-18 -0.012500000000000021511"
                rpy="0 0 0" />
            <mass value="0.0090000000000000010547" />
            <inertia ixx="1.1139804559497151344e-06" ixy="5.1307049366483959977e-31"
                ixz="-1.0982108385939740633e-29" iyy="3.8619585138359632849e-06"
                iyz="-1.2982143039433436691e-22" izz="4.0384389697856793485e-06" />
        </inertial>
    </link>

    <link name="BRUL">
        <visual>
            <origin xyz="0 0 -0.044999999999999998335"
                rpy="-1.570796326794896558 -1.570796326794896558 0" />
            <geometry>
                <mesh filename="../meshes/V2.7/leg_upper_sim.stl" />
            </geometry>
            <material name="leg_upper_sim_material">
                <color
                    rgba="0.90980392156862743835 0.57254901960784310155 0.16470588235294117418 1.0" />
            </material>
        </visual>
        <collision>
            <origin xyz="0 0 -0.044999999999999998335"
                rpy="-1.570796326794896558 -1.570796326794896558 0" />
            <geometry>
                <mesh filename="../meshes/V2.7/leg_upper_sim.stl" />
            </geometry>
        </collision>
        <inertial>
            <origin
                xyz="5.3710312285871194511e-18 -0.049999999999999995837 -0.022499999999999992228"
                rpy="0 0 0" />
            <mass value="0.37600000000000000089" />
            <inertia ixx="0.00054596018323756537703" ixy="-4.0997350286313552261e-21"
                ixz="-6.8497463608921523299e-29" iyy="9.0305640199817051859e-05"
                iyz="-5.2442904977854927958e-28" izz="0.00050936582343738242076" />
        </inertial>
    </link>

    <link name="BRLL">
        <visual>
            <origin
                xyz="-6.9388939039072283776e-18 -1.1102230246251565404e-16 -0.025000000000000022204"
                rpy="-1.570796326794896558 -1.570796326794896558 0" />
            <geometry>
                <mesh filename="../meshes/V2.7/leg_lower_sim.stl" />
            </geometry>
            <material name="leg_lower_sim_material">
                <color rgba="1 0.7568627450980391913 0.054901960784313724728 1.0" />
            </material>
        </visual>
        <collision>
            <origin
                xyz="-6.9388939039072283776e-18 -1.1102230246251565404e-16 -0.025000000000000022204"
                rpy="-1.570796326794896558 -1.570796326794896558 0" />
            <geometry>
                <mesh filename="../meshes/V2.7/leg_lower_sim.stl" />
            </geometry>
        </collision>
        <inertial>
            <origin
                xyz="-1.5120699944732869491e-18 -0.061136909622976041978 -0.012500000000000019776"
                rpy="0 0 0" />
            <mass value="0.058000000000000002942" />
            <inertia ixx="9.3657217382847482521e-05" ixy="-8.5115057308495856364e-23"
                ixz="1.9982045116986763224e-30" iyy="9.3296789238021381879e-06"
                iyz="-2.3507485930776857776e-29" izz="9.6945229639982987888e-05" />
        </inertial>
    </link>

    <link name="BRW">
        <visual>
            <origin xyz="-0.087087206542491912842 -0.027046862989664077759 -0.014999999999999985567"
                rpy="-1.570796326794896558 -1.570796326794896558 0" />
            <geometry>
                <mesh filename="../meshes/V2.7/wheel_sim.stl" />
            </geometry>
            <material name="wheel_sim_material">
                <color
                    rgba="0.64705882352941179736 0.64705882352941179736 0.64705882352941179736 1.0" />
            </material>
        </visual>
        <collision>
            <origin xyz="-0.087087206542491912842 -0.027046862989664077759 -0.014999999999999985567"
                rpy="-1.570796326794896558 -1.570796326794896558 0" />
            <geometry>
                <mesh filename="../meshes/V2.7/wheel_sim.stl" />
            </geometry>
        </collision>
        <inertial>
            <origin xyz="-1.379277327633000212e-17 0 -0.007499999999999986712" rpy="0 0 0" />
            <mass value="0.036999999999999998168" />
            <inertia ixx="2.3186407739588018592e-05" ixy="1.7556990739572654568e-22"
                ixz="-3.796197600592832203e-29" iyy="2.3186407739588025368e-05"
                iyz="2.7750954066034261114e-30" izz="4.5033754578493196004e-05" />
        </inertial>
    </link>

    <joint name="BRW joint" type="revolute">
        <origin xyz="4.649058915617843013e-16 -0.10000000000000253131 -0.02550000000000007816"
            rpy="5.280391695094608967e-16 1.990347176363573344e-16 -1.5707963267948996666" />
        <parent link="BRLL" />
        <child link="BRW" />
        <axis xyz="0 0 1" />
        <limit effort="3.43" velocity="1.5707" />
        <joint_properties friction="0.0" />
    </joint>

    <joint name="BRK joint" type="revolute">
        <origin xyz="6.9388939039072283776e-18 -0.099999999999999977796 -0.045499999999999998779"
            rpy="-7.1059545805497230997e-18 4.6448451335924615758e-18 3.141592653589793116" />
        <parent link="BRUL" />
        <child link="BRLL" />
        <axis xyz="0 0 1" />
        <limit effort="6.864655" velocity="8.055365759832842" lower="0" upper="3.141592653589793116" />
        <joint_properties friction="0.0" />
    </joint>

    <joint name="BRHL joint" type="revolute">
        <origin xyz="0.055499999999999979905 -2.0816681711721685133e-17 -0.012499999999999955591"
            rpy="1.570796326794896558 2.5226393505124359703e-17 -1.5707963267948970021" />
        <parent link="BRH" />
        <child link="BRUL" />
        <axis xyz="0 0 1" />
        <limit effort="6.864655" velocity="8.055365759832842" lower="-3.141592653589793116" upper="0" />
        <joint_properties friction="0.0" />
    </joint>

    <joint name="BRHU joint" type="revolute">
        <origin xyz="-0.058914152254507468065 0.28877996192283483801 -0.018878734177435064351"
            rpy="-1.6580628063677369521 -1.1592871143413035731e-09 3.1415926403390637134" />
        <parent link="trunk" />
        <child link="BRH" />
        <axis xyz="0 0 1" />
        <limit effort="6.864655" velocity="8.055365759832842" lower="-0.75" upper="0.75" />
        <joint_properties friction="0.0" />
    </joint>


</robot>